<?xml version="1.0"?>

<robot name="evarobot" xmlns:xacro="http://ros.org/wiki/xacro">
	<xacro:macro name="evarobot_wheel" params="prefix joint_x joint_y joint_z joint_roll joint_pitch joint_yaw cylinder_length cylinder_radius parent_link">

		<link name="${prefix}_link">
			<collision>
				<origin rpy="1.57075 0 0" xyz="0 0 0"/>
				<geometry>
					<cylinder length="${cylinder_length}" radius="${cylinder_radius}"/>
				</geometry>
			</collision>

			
			<visual>
				<origin rpy="0 0 ${pi/2}" xyz="0 0 0"/> 
				<geometry>
					 <mesh filename="package://evarobot_description/meshes/rim.stl" scale="1 1 1"/> 
				</geometry>
				<material name="Grey"/>
			</visual>
			

			<inertial>
				<origin rpy="1.57075 0 0" xyz="0 0 0"/>
				<mass value="0.85"/>
				<inertia
					ixx="0.001" ixy="0" ixz="0"
					iyy="0.001" iyz="0"
					izz="0.001"/>
			</inertial>

		</link>
		
		<gazebo reference="${prefix}_link">
			<material>Gazebo/Grey</material>
	    <mu1>1.0</mu1>
	    <mu2>1.0</mu2>
	    <kp>1000000.0</kp>
	    <kd>100.0</kd>
	    <minDepth>0.001</minDepth>
	    <maxVel>1.0</maxVel>		
		</gazebo>

		<joint name="${prefix}_joint" type="continuous">
			<axis xyz="0 1 0"/>
			<parent link="${parent_link}"/>
			<child link="${prefix}_link"/>
			<origin rpy="${joint_roll} ${joint_pitch} ${joint_yaw}" xyz="${joint_x} ${joint_y} ${joint_z}"/>
		</joint>
		
		
		
		
		<link name="${prefix}tire_link">
			<collision>
				<origin rpy="1.57075 0 0" xyz="0 0 0"/>
				<geometry>
					<cylinder length="0.001" radius="0.001"/>
				</geometry>
			</collision>
			
			<visual>
				<origin rpy="0 0 ${pi/2}" xyz="0 0 0"/>
				<geometry>
					<mesh filename="package://evarobot_description/meshes/tire.stl" scale="1 1 1"/> 
				</geometry>
				<material name="Black"/>
			</visual>
			
			<inertial>
				<origin xyz="0 0 0" rpy="0 0 0"/>
				<mass value="0.001"/>
				<inertia
					ixx="0.001" ixy="0" ixz="0"
					iyy="0.001" iyz="0"
					izz="0.001"/>
			</inertial>
			
		</link>
		
		<gazebo reference="${prefix}tire_link">
			<material>Gazebo/Black</material>
		</gazebo>	

		<joint name="${prefix}tire_joint" type="continuous">
			<axis xyz="0 1 0"/>
			<parent link="${prefix}_link"/>
			<child link="${prefix}tire_link"/>
			<origin rpy="0 0 0" xyz="0.0 0.0 0.0"/>
		</joint>
		
	</xacro:macro>
</robot>


