<?xml version="1.0"?>
<robot name="evarobot">

<!-- Base -->
  <link name="base_link">
    <collision>
      <origin rpy="0 0 0" xyz="0 0 0"/>
      <geometry>
		<!--  <box size="0.3445 0.251 0.3005"/> -->
		<box size="0.30 0.251 0.3005"/>
      </geometry>
    </collision>

    <visual>
     <origin xyz="0.05 0 -0.1475" rpy="0 0 1.5708" /> 
    <!--  <origin xyz="0.0 0 0" rpy="0 0 0" /> -->
      <geometry>
    <!--    <box size="0.3445 0.251 0.3005"/> -->
        <mesh filename="package://evarobot_description/meshes/evarobot_all.stl" scale="0.001 0.001 0.001"/> 
      </geometry>
      <material name="blue">
        <color rgba="0 0 .8 1"/>
      </material>
    </visual>

    <inertial>
      <origin xyz="0 0 0" rpy="0 0 0"/>
      <mass value="5"/>
      <inertia
        ixx="5.0" ixy="0.0" ixz="0.0"
        iyy="5.0" iyz="0.0"
        izz="5.0"/>
    </inertial>
  </link>

  <!-- Sol Teker -->
    
   <link name="left_front_wheel">
    <collision>
      <origin rpy="1.57075 0 0" xyz="0 0 0"/>
      <geometry>
        <cylinder length=".024" radius="0.0675"/>
      </geometry>
    </collision>
    
   <!--<visual>
	   <origin rpy="0 -1.57075 0" xyz="0 0 +0.01"/>
      <geometry>
		 <cylinder length=".024" radius="0.0675"/>  
		     <mesh filename="package://evarobot_description/meshes/wheel.stl" scale="0.001 0.001 0.001"/>
      </geometry>
      <material name="black"/> 		
    </visual>-->
    
    <inertial>
      <origin xyz="0 0 0" rpy="0 0 0"/>
      <mass value="0.75"/>
      <inertia ixx="1e-2" ixy="0" ixz="0" iyy="1e-2" iyz="0" izz="1e-2" />
    </inertial>
    
  </link>
  
  <joint name="left_front_wheel_joint" type="continuous">
    <axis xyz="0 1 0"/>
    <parent link="base_link"/>
    <child link="left_front_wheel"/>
    <origin rpy="0 0 0" xyz="0.04975 0.1375 -0.11775"/>
    <limit effort="100" velocity="100"/>
    <joint_properties damping="0.0" friction="0.0"/>
  </joint>
 
 <!-- Sag Teker -->
 
   <link name="right_front_wheel">
	  <collision>
      <origin rpy="1.57075 0 0" xyz="0 0 0"/>
      <geometry>
        <cylinder length=".024" radius="0.0675"/>
      </geometry>
    </collision>
       
  <!--  <visual>
		<origin rpy="0 -1.57075 0" xyz="0 0 -0.01"/>
      <geometry>
     <cylinder length=".024" radius="0.0675"/> 
     <mesh filename="package://evarobot_description/meshes/wheel.stl" scale="0.001 0.001 0.001"/>
      </geometry>
      <material name="black"/> 		
    </visual>
    -->
    <inertial>
      <origin xyz="0 0 0" rpy="0 0 0"/>
      <mass value="0.75"/>
      <inertia ixx="1e-2" ixy="0" ixz="0" iyy="1e-2" iyz="0" izz="1e-2" />
    </inertial>
    
  </link>
  
  <joint name="right_front_wheel_joint" type="continuous">
    <axis xyz="0 1 0"/>
    <parent link="base_link"/>
    <child link="right_front_wheel"/>
    <origin rpy="0 0 0" xyz="0.04975 -0.1375 -0.11775"/>
    <limit effort="100" velocity="100"/>
    <joint_properties damping="0.0" friction="0.0"/>
  </joint>
  
 
   <!-- Caster -->
  <link name="caster_wheel">
	<collision>
      <origin rpy="0 0 0" xyz="0 0 0"/>
      <geometry>
        <sphere radius="0.035"/>
      </geometry>
    </collision>
    	  
    <visual>
      <geometry>
        <sphere radius="0.035"/>
      </geometry>
      <material name="black">
        <color rgba="0 0 0 1"/>
      </material>
    </visual>
    
    <inertial>
      <origin xyz="0 0 0" rpy="0 0 0"/>
      <mass value="5"/>
      <inertia ixx="1e-6" ixy="0" ixz="0" iyy="1e-6" iyz="0" izz="1e-6" />
    </inertial>
  </link>
  
  <gazebo reference="caster_wheel">
      <mu1>0.2</mu1>
      <mu2>0.2</mu2>
    </gazebo>
  
  <joint name="caster_wheel_joint" type="continuous">
    <parent link="base_link"/>
    <child link="caster_wheel"/>
    <origin rpy="-1.57075 0 0" xyz="-0.1 0 -0.15025"/>
 <!--   <axis xyz="0.707106781 0 0.707106781"/> -->
    <axis xyz="0.577350269 0.577350269 0.577350269"/>
    <limit effort="100" velocity="100"/>
    <joint_properties damping="0.0" friction="0.0"/>
  </joint>


  
  <!-- Hokuyo Laser -->
<!--  <link name="laser">
    <collision>
      <origin xyz="0 0 0" rpy="0 0 0"/>
      <geometry>
    <box size="0.1 0.1 0.1"/>
      </geometry>
    </collision>

    <visual>
      <origin xyz="0 0 0" rpy="0 0 0"/>
      <geometry>
        <mesh filename="package://evarobot_description/meshes/hokuyo.dae"/>
      </geometry>
    </visual>

    <inertial>
      <mass value="1e-5" />
      <origin xyz="0 0 0" rpy="0 0 0"/>
      <inertia ixx="1e-6" ixy="0" ixz="0" iyy="1e-6" iyz="0" izz="1e-6" />
    </inertial>
  </link>
  
  -->

  <!-- Hokuyo Laser -->
<!-- 
  <joint name="hokuyo_joint" type="fixed">
    <axis xyz="0 1 0" />
    <origin xyz="-0.09 0 0.4275" rpy="0 0 -1.5708"/>
    <parent link="base_link"/>
    <child link="laser"/>
  </joint>
  -->
  <!-- Hokuyo Laser Plugin -->
 <!-- <gazebo reference="laser">
    <sensor type="gpu_ray" name="head_hokuyo_sensor">
      <pose>0 0 0 0 0 0</pose>
      <visualize>false</visualize>
      <update_rate>40</update_rate>
      <ray>
        <scan>
          <horizontal>
            <samples>720</samples>
            <resolution>1</resolution>
            <min_angle>-3.1416</min_angle>
            <max_angle>3.1416</max_angle>
          </horizontal>
        </scan>
        <range>
          <min>0.5</min>
          <max>5.0</max>
          <resolution>0.1</resolution>
        </range>
        <noise>
          <type>gaussian</type> -->
          <!-- Noise parameters based on published spec for Hokuyo laser
               achieving "+-30mm" accuracy at range < 10m.  A mean of 0.0m and
               stddev of 0.01m will put 99.7% of samples within 0.03m of the true
               reading. -->
        <!--  <mean>0.0</mean>
          <stddev>0.01</stddev>
        </noise>
      </ray>
      
  	  <plugin name="gazebo_ros_head_hokuyo_controller" filename="libgazebo_ros_gpu_laser.so">
		<robotNamespace>sensor</robotNamespace>
        <topicName>scan</topicName>
        <frameName>laser</frameName>
      </plugin>
    </sensor>
  </gazebo>
  -->
  <gazebo>
  <plugin name="gazebo_ros_control" filename="libgazebo_ros_control.so">
    <robotNamespace>/rrbot</robotNamespace>
  </plugin>
</gazebo>


  <link name="camera_depth_optical_frame">
    <collision>
      <origin xyz="0 0 0" rpy="0 0 0"/>
      <geometry>
    <box size="0.1 0.1 0.1"/>
      </geometry>
    </collision>


    <inertial>
      <mass value="1e-5" />
      <origin xyz="0 0 0" rpy="0 0 0"/>
      <inertia ixx="1e-6" ixy="0" ixz="0" iyy="1e-6" iyz="0" izz="1e-6" />
    </inertial>
  </link>
  
  <!-- Kinect joint -->
   <joint name="kinect_jointx" type="fixed">
    <axis xyz="0 1 0" />
    <origin xyz="-0.09 0 0.4275" rpy="-1.5707  0 -1.5707"/>
    <parent link="base_link"/>
    <child link="camera_depth_optical_frame"/>
  </joint>

  
 <!-- Kinect Link -->
  <link name="sensor/kinect">
    <collision>
      <origin xyz="0 0 0" rpy="0 0 0"/>
      <geometry>
    <box size="0.1 0.1 0.1"/>
      </geometry>
    </collision>

    <visual>
      <origin xyz="0 0 0" rpy="0 0 0"/>
      <geometry>
        <mesh filename="package://evarobot_description/meshes/kinect.dae"/>
      </geometry>
    </visual>

    <inertial>
      <mass value="1e-5" />
      <origin xyz="0 0 0" rpy="0 0 0"/>
      <inertia ixx="1e-6" ixy="0" ixz="0" iyy="1e-6" iyz="0" izz="1e-6" />
    </inertial>
  </link>
  
  <!-- Kinect joint -->
   <joint name="kinect_joint" type="fixed">
    <axis xyz="0 1 0" />
    <origin xyz="-0.09 0 0.4275" rpy="0 0 0"/>
    <parent link="base_link"/>
    <child link="sensor/kinect"/>
  </joint>
  
  <!-- Kinect plugin -->
  
<gazebo reference="sensor/kinect">
    <sensor type="depth" name="openni_camera_camera">       
        <always_on>1</always_on>
        <visualize>false</visualize>             
        <camera>
            <horizontal_fov>1.047</horizontal_fov>  
            <image>
                <width>160</width>
                <height>120</height>
                <format>R8G8B8</format>
            </image>
            <depth_camera>

            </depth_camera>
            <clip>
                <near>0.1</near>
                <far>100</far>
            </clip>
        </camera>
  <plugin name="kinect_controller" filename="libgazebo_ros_openni_kinect.so">
	
    <baseline>0.2</baseline>
    <alwaysOn>true</alwaysOn>
    <updateRate>1.0</updateRate>
    <cameraName>kinect_ir</cameraName>
    <imageTopicName>/kinect/depth/image_raw</imageTopicName>
    <cameraInfoTopicName>/kinect/depth/camera_info</cameraInfoTopicName>
    <depthImageTopicName>/kinect/depth/image_raw</depthImageTopicName>
    <depthImageInfoTopicName>/kinect/depth/camera_info</depthImageInfoTopicName>
    <pointCloudTopicName>/kinect/depth/points</pointCloudTopicName>
    <frameName>evarobot/kinect_link</frameName>
    <pointCloudCutoff>0.5</pointCloudCutoff>
    <distortionK1>0.00000001</distortionK1>
    <distortionK2>0.00000001</distortionK2>
    <distortionK3>0.00000001</distortionK3>
    <distortionT1>0.00000001</distortionT1>
    <distortionT2>0.00000001</distortionT2>
    <CxPrime>0</CxPrime>
    <Cx>0</Cx>
    <Cy>0</Cy>
    <focalLength>0</focalLength>
    <hackBaseline>0</hackBaseline>
  </plugin>
    </sensor>
</gazebo>

<!-- ////////////////////////////////////////////////////////////////// -->
<!-- ////////////////////////////   BUMPER   ////////////////////////// -->
<!-- ////////////////////////////////////////////////////////////////// -->

<!-- Bumper0 Link -->
  <link name="bumper0">
    <collision>
      <origin xyz="0 0 0" rpy="0 0 0"/>
      <geometry>
		<box size="0.015 0.105 0.020"/>
      </geometry>
    </collision>

    <visual>
      <origin xyz="0 0 0" rpy="0 0 0"/>
      <geometry>
		<box size="0.015 0.105 0.020"/>
      </geometry>
    </visual>

    <inertial>
      <mass value="1e-5" />
      <origin xyz="0 0 0" rpy="0 0 0"/>
      <inertia ixx="1e-6" ixy="0" ixz="0" iyy="1e-6" iyz="0" izz="1e-6" />
    </inertial>
  </link>
  
  <!-- Bumper0 joint -->
   <joint name="bumper0_joint" type="fixed">
    <axis xyz="0 1 0" />
    <origin xyz="0.1575 -0.105 -0.1345" rpy="0 0 -0.34"/>
    <parent link="base_link"/>
    <child link="bumper0"/>
  </joint>
  
  <!-- Bumper0 plugin -->
	<gazebo reference="bumper0">
	  <sensor name="bumper0" type="contact">
		<always_on>true</always_on>
		<update_rate>10.0</update_rate>
		<contact>
		  <collision>bumper0_collision</collision>
		</contact>
		<plugin name="bumper0_plugin" filename="libim_gazebo_ros_bumper.so">
		  <bumperTopicName>bumper0_topic</bumperTopicName>
		  <frameName>bumper0_frame</frameName>
		</plugin>
	  </sensor>
	</gazebo>
	
<!-- Bumper1 Link -->
  <link name="bumper1">
    <collision>
      <origin xyz="0 0 0" rpy="0 0 0"/>
      <geometry>
		<box size="0.015 0.10 0.020"/>
      </geometry>
    </collision>

    <visual>
      <origin xyz="0 0 0" rpy="0 0 0"/>
      <geometry>
		<box size="0.015 0.10 0.020"/>
      </geometry>
    </visual>

    <inertial>
      <mass value="1e-5" />
      <origin xyz="0 0 0" rpy="0 0 0"/>
      <inertia ixx="1e-6" ixy="0" ixz="0" iyy="1e-6" iyz="0" izz="1e-6" />
    </inertial>
  </link>
  
  <!-- Bumper1 joint -->
   <joint name="bumper1_joint" type="fixed">
    <axis xyz="0 1 0" />
    <origin xyz="0.1775 0 -0.1345" rpy="0 0 0"/>
    <parent link="base_link"/>
    <child link="bumper1"/>
  </joint>
  
  <!-- Bumper1 plugin -->
	<gazebo reference="bumper1">
	  <sensor name="bumper1" type="contact">
		<always_on>true</always_on>
		<update_rate>10.0</update_rate>
		<contact>
		  <collision>bumper1_collision</collision>
		</contact>
		<plugin name="bumper1_plugin" filename="libim_gazebo_ros_bumper.so">
		  <bumperTopicName>bumper1_topic</bumperTopicName>
		  <frameName>bumper1_frame</frameName>
		</plugin>
	  </sensor>
	</gazebo>
	
<!-- Bumper2 Link -->
  <link name="bumper2">
    <collision>
      <origin xyz="0 0 0" rpy="0 0 0"/>
      <geometry>
		<box size="0.015 0.105 0.020"/>
      </geometry>
    </collision>

    <visual>
      <origin xyz="0 0 0" rpy="0 0 0"/>
      <geometry>
		<box size="0.015 0.105 0.020"/>
      </geometry>
    </visual>

    <inertial>
      <mass value="1e-5" />
      <origin xyz="0 0 0" rpy="0 0 0"/>
      <inertia ixx="1e-6" ixy="0" ixz="0" iyy="1e-6" iyz="0" izz="1e-6" />
    </inertial>
  </link>
  
  <!-- Bumper2 joint -->
   <joint name="bumper2_joint" type="fixed">
    <axis xyz="0 1 0" />
    <origin xyz="0.1605 0.105 -0.1345" rpy="0 0 0.34"/>
    <parent link="base_link"/>
    <child link="bumper2"/>
  </joint>
  
  <!-- Bumper2 plugin -->
	<gazebo reference="bumper2">
	  <sensor name="bumper2" type="contact">
		<always_on>true</always_on>
		<update_rate>10.0</update_rate>
		<contact>
		  <collision>bumper2_collision</collision>
		</contact>
		<plugin name="bumper2_plugin" filename="libim_gazebo_ros_bumper.so">
		  <bumperTopicName>bumper2_topic</bumperTopicName>
		  <frameName>bumper2_frame</frameName>
		</plugin>
	  </sensor>
	</gazebo>
	
	
<!-- ////////////////////////////////////////////////////////////////// -->
<!-- ////////////////////////   BUMPER (END) ////////////////////////// -->
<!-- ////////////////////////////////////////////////////////////////// -->


  <joint name="imu_joint" type="fixed">
    <axis xyz="1 0 0"/> <!-- 0 1 0 -->
    <origin xyz="0 0 0.19"/>
    <parent link="base_link"/>
    <child link="sensor/imu"/>
  </joint>


<link name="sensor/imu">
  <inertial>
    <mass value="0.001"/>
    <origin rpy="0 0 0" xyz="0 0 0"/>
    <inertia ixx="0.0001" ixy="0" ixz="0" iyy="0.000001" iyz="0" izz="0.0001"/>
  </inertial>
  <visual>
    <origin rpy="0 0 0" xyz="0 0 0"/>
    <geometry>
      <box size="0.001 0.001 0.001"/>
    </geometry>
  </visual>
  <collision>
    <origin rpy="0 0 0" xyz="0 0 0"/>
    <geometry>
      <box size=".001 .001 .001"/>
    </geometry>
  </collision>
</link>


<gazebo>
	<plugin name="imu_plugin" filename="libgazebo_ros_imu.so">
        <alwaysOn>true</alwaysOn>
        <robotNamespace>gazebo</robotNamespace>    
        <frameName>imu_frame</frameName>   
        <bodyName>imu_link</bodyName>
        <topicName>sensor/IMU</topicName>
        <serviceName>imu_service</serviceName>
        <gaussianNoise>0.0</gaussianNoise>
        <updateRate>10.0</updateRate> 
    </plugin>
</gazebo>

<!-- SONAR -->


  <joint name="sensor/sonar0" type="fixed">
    <axis xyz="1 0 0"/> <!-- 0 1 0 -->
    <origin xyz="0.14 0 0.0275"/>
    <parent link="base_link"/>
    <child link="sensor/sonar0"/>
  </joint>

<link name="sensor/sonar0">
      <inertial>
        <mass value="0.001" />
        <origin xyz="0 0 0" rpy="0 0 0" />
        <inertia ixx="0.000000017" ixy="0" ixz="0" iyy="0.000000017" iyz="0" izz="0.000000017" />
      </inertial>
      <visual>
        <origin xyz="0 0 0" rpy="0 0 0" />
        <geometry>
          <mesh filename="package://evarobot_description/meshes/sonar_sensor/max_sonar_ez4.dae"/>
        </geometry>
      </visual>
      <collision>
        <origin xyz="0 0 0" rpy="0 0 0" />
        <geometry>
          <box size="0.01 0.01 0.01" />
        </geometry>
      </collision>
    </link>

<!-- Sonar0 Plugin -->
 <gazebo reference="sensor/sonar0">
      <sensor type="ray" name="sonar0">
	  <pose>0 0 0 0 0 0</pose>
	<ray>
          <scan>
            <horizontal>
      	      <samples>320</samples>
      	      <resolution>1</resolution>
      	      <min_angle>-0.479965544</min_angle>
      	      <max_angle>0.479965544</max_angle>
            </horizontal>
          </scan>
          <range>
            <min>0.02</min>
            <max>5</max>
            <resolution>0.01</resolution>
          </range>
	</ray>
	<plugin name="sonar0_plugin" filename="libim_gazebo_ros_sonar.so">
          <topicName>gazebo/sensor/Sonar0</topicName>
          <frameName>sensor/sonar0</frameName>
	  <frameId>sonar_base_link0</frameId>
	  <radiation>ultrasound</radiation>
	  <fov>0.05</fov>
	  <gaussianNoise>0</gaussianNoise>
	</plugin>
        <always_on>1</always_on>
        <update_rate>4</update_rate>
        <visualize>false</visualize>
      </sensor>
    </gazebo>
    
    <!-- Sonar 1 -->
  <joint name="sonar1_joint" type="fixed">
    <axis xyz="1 0 0"/> <!-- 0 1 0 -->
    <origin xyz="0.0 0.145 0.0275" rpy="0 0 1.5708"/>
    <parent link="base_link"/>
    <child link="sensor/sonar1"/>
  </joint>

<link name="sensor/sonar1">
      <inertial>
        <mass value="0.001" />
        <origin xyz="0 0 0" rpy="0 0 0" />
        <inertia ixx="0.000000017" ixy="0" ixz="0" iyy="0.000000017" iyz="0" izz="0.000000017" />
      </inertial>
      <visual>
        <origin xyz="0 0 0" rpy="0 0 0" />
        <geometry>
          <mesh filename="package://evarobot_description/meshes/sonar_sensor/max_sonar_ez4.dae"/>
        </geometry>
      </visual>
      <collision>
        <origin xyz="0 0 0" rpy="0 0 0" />
        <geometry>
          <box size="0.01 0.01 0.01" />
        </geometry>
      </collision>
    </link>

<!-- Sonar1 Plugin -->
 <gazebo reference="sensor/sonar1">
      <sensor type="ray" name="sonar1">
	  <pose>0 0 0 0 0 0</pose>
	<ray>
          <scan>
            <horizontal>
      	      <samples>320</samples>
      	      <resolution>1</resolution>
      	      <min_angle>-0.479965544</min_angle>
      	      <max_angle>0.479965544</max_angle>
            </horizontal>
          </scan>
          <range>
            <min>0.02</min>
            <max>5</max>
            <resolution>0.01</resolution>
          </range>
	</ray>
	<plugin name="sonar1_plugin" filename="libim_gazebo_ros_sonar.so">
          <topicName>gazebo/sensor/Sonar1</topicName>
          <frameName>sensor/sonar1</frameName>
	  <frameId>sonar_base_link1</frameId>
	  <radiation>ultrasound</radiation>
	  <fov>0.05</fov>
	  <gaussianNoise>0</gaussianNoise>
	</plugin>
        <always_on>1</always_on>
        <update_rate>4</update_rate>
        <visualize>false</visualize>
      </sensor>
    </gazebo>
    
      <!-- Sonar 2 -->
  <joint name="sonar2_joint" type="fixed">
    <axis xyz="1 0 0"/> <!-- 0 1 0 -->
     <origin xyz="-0.14 0 0.0275" rpy="0 0 3.1416"/>
    <parent link="base_link"/>
    <child link="sensor/sonar2"/>
  </joint>

<link name="sensor/sonar2">
      <inertial>
        <mass value="0.001" />
        <origin xyz="0 0 0" rpy="0 0 0" />
        <inertia ixx="0.000000017" ixy="0" ixz="0" iyy="0.000000017" iyz="0" izz="0.000000017" />
      </inertial>
      <visual>
        <origin xyz="0 0 0" rpy="0 0 0" />
        <geometry>
          <mesh filename="package://evarobot_description/meshes/sonar_sensor/max_sonar_ez4.dae"/>
        </geometry>
      </visual>
      <collision>
        <origin xyz="0 0 0" rpy="0 0 0" />
        <geometry>
          <box size="0.01 0.01 0.01" />
        </geometry>
      </collision>
    </link>

<!-- Sonar2 Plugin -->
 <gazebo reference="sensor/sonar2">
      <sensor type="ray" name="sonar2">
	  <pose>0 0 0 0 0 0</pose>
	<ray>
          <scan>
            <horizontal>
      	      <samples>320</samples>
      	      <resolution>1</resolution>
      	      <min_angle>-0.479965544</min_angle>
      	      <max_angle>0.479965544</max_angle>
            </horizontal>
          </scan>
          <range>
            <min>0.02</min>
            <max>5</max>
            <resolution>0.01</resolution>
          </range>
	</ray>
	<plugin name="sonar2_plugin" filename="libim_gazebo_ros_sonar.so">
          <topicName>gazebo/sensor/Sonar2</topicName>
          <frameName>sensor/sonar2</frameName>
	  <frameId>sonar_base_link2</frameId>
	  <radiation>ultrasound</radiation>
	  <fov>0.05</fov>
	  <gaussianNoise>0</gaussianNoise>
	</plugin>
        <always_on>1</always_on>
        <update_rate>4</update_rate>
        <visualize>false</visualize>
      </sensor>
    </gazebo>
    
  
     <!-- Sonar 3 -->
  <joint name="sonar3_joint" type="fixed">
    <axis xyz="1 0 0"/> <!-- 0 1 0 -->
    <origin xyz="0.0 -0.145 0.0275" rpy="0 0 -1.5708"/>
    <parent link="base_link"/>
    <child link="sensor/sonar3"/>
  </joint>

<link name="sensor/sonar3">
      <inertial>
        <mass value="0.001" />
        <origin xyz="0 0 0" rpy="0 0 0" />
        <inertia ixx="0.000000017" ixy="0" ixz="0" iyy="0.000000017" iyz="0" izz="0.000000017" />
      </inertial>
      <visual>
        <origin xyz="0 0 0" rpy="0 0 0" />
        <geometry>
          <mesh filename="package://evarobot_description/meshes/sonar_sensor/max_sonar_ez4.dae"/>
        </geometry>
      </visual>
      <collision>
        <origin xyz="0 0 0" rpy="0 0 0" />
        <geometry>
          <box size="0.01 0.01 0.01" />
        </geometry>
      </collision>
    </link>

<!-- Sonar3 Plugin -->
 <gazebo reference="sensor/sonar3">
      <sensor type="ray" name="sonar3">
	  <pose>0 0 0 0 0 0</pose>
	<ray>
          <scan>
            <horizontal>
      	      <samples>320</samples>
      	      <resolution>1</resolution>
      	      <min_angle>-0.479965544</min_angle>
      	      <max_angle>0.479965544</max_angle>
            </horizontal>
          </scan>
          <range>
            <min>0.02</min>
            <max>5</max>
            <resolution>0.01</resolution>
          </range>
	</ray>
	<plugin name="sonar3_plugin" filename="libim_gazebo_ros_sonar.so">
          <topicName>gazebo/sensor/Sonar3</topicName>
          <frameName>sensor/sonar3</frameName>
	  <frameId>sonar_base_link3</frameId>
	  <radiation>ultrasound</radiation>
	  <fov>0.05</fov>
	  <gaussianNoise>0</gaussianNoise>
	</plugin>
        <always_on>1</always_on>
        <update_rate>4</update_rate>
        <visualize>false</visualize>
      </sensor>
    </gazebo>
  
    
     <!-- IR 0 -->
  <joint name="ir0_joint" type="fixed">
    <axis xyz="1 0 0"/> <!-- 0 1 0 -->
    <origin xyz="0.1175 -0.085 -0.1075" rpy="0 0 -0.60"/>
    <parent link="base_link"/>
    <child link="sensor/ir0"/>
  </joint>

<link name="sensor/ir0">
      <inertial>
        <mass value="0.001" />
        <origin xyz="0 0 0" rpy="0 0 0" />
        <inertia ixx="0.000000017" ixy="0" ixz="0" iyy="0.000000017" iyz="0" izz="0.000000017" />
      </inertial>
      <visual>
        <origin xyz="0 0 0" rpy="0 0 0" />
        <geometry>
          <mesh filename="package://evarobot_description/meshes/sonar_sensor/max_sonar_ez4.dae"/>
        </geometry>
      </visual>
      <collision>
        <origin xyz="0 0 0" rpy="0 0 0" />
        <geometry>
          <box size="0.01 0.01 0.01" />
        </geometry>
      </collision>
    </link>

<!-- IR0 Plugin -->
 <gazebo reference="sensor/ir0">
      <sensor type="ray" name="ir0">
	  <pose>0 0 0 0 0 0</pose>
	<ray>
          <scan>
            <horizontal>
      	      <samples>320</samples>
      	      <resolution>1</resolution>
      	      <min_angle>-0.001</min_angle>
      	      <max_angle>0.001</max_angle>
            </horizontal>
          </scan>
          <range>
            <min>0.02</min>
            <max>5</max>
            <resolution>0.01</resolution>
          </range>
	</ray>
	<plugin name="ir0_plugin" filename="libim_gazebo_ros_sonar.so">
          <topicName>gazebo/sensor/IR0</topicName>
          <frameName>sensor/ir0</frameName>
	  <frameId>sensor/ir1</frameId>
	  <radiation>infrared</radiation>
	  <fov>0.05</fov>
	  <gaussianNoise>0</gaussianNoise>
	</plugin>
        <always_on>1</always_on>
        <update_rate>4</update_rate>
        <visualize>false</visualize>
      </sensor>
    </gazebo>  
    
    
    <!-- IR 1 -->
  <joint name="ir1_joint" type="fixed">
    <axis xyz="1 0 0"/> <!-- 0 1 0 -->
    <origin xyz="0.1475 0 -0.1075" rpy="0 0 0"/>
    <parent link="base_link"/>
    <child link="sensor/ir1"/>
  </joint>

<link name="sensor/ir1">
      <inertial>
        <mass value="0.001" />
        <origin xyz="0 0 0" rpy="0 0 0" />
        <inertia ixx="0.000000017" ixy="0" ixz="0" iyy="0.000000017" iyz="0" izz="0.000000017" />
      </inertial>
      <visual>
        <origin xyz="0 0 0" rpy="0 0 0" />
        <geometry>
          <mesh filename="package://evarobot_description/meshes/sonar_sensor/max_sonar_ez4.dae"/>
        </geometry>
      </visual>
      <collision>
        <origin xyz="0 0 0" rpy="0 0 0" />
        <geometry>
          <box size="0.01 0.01 0.01" />
        </geometry>
      </collision>
    </link>

<!-- IR1 Plugin -->
 <gazebo reference="sensor/ir1">
      <sensor type="ray" name="ir1">
	  <pose>0 0 0 0 0 0</pose>
	<ray>
          <scan>
            <horizontal>
      	      <samples>320</samples>
      	      <resolution>1</resolution>
      	      <min_angle>-0.001</min_angle>
      	      <max_angle>0.001</max_angle>
            </horizontal>
          </scan>
          <range>
            <min>0.02</min>
            <max>5</max>
            <resolution>0.01</resolution>
          </range>
	</ray>
	<plugin name="ir1_plugin" filename="libim_gazebo_ros_sonar.so">
          <topicName>gazebo/sensor/IR1</topicName>
          <frameName>sensor/ir1</frameName>
	  <frameId>sensor/ir1</frameId>
	  <radiation>infrared</radiation>
	  <fov>0.05</fov>
	  <gaussianNoise>0</gaussianNoise>
	</plugin>
        <always_on>1</always_on>
        <update_rate>4</update_rate>
        <visualize>false</visualize>
      </sensor>
    </gazebo>   
    
    <!-- IR 2 -->
  <joint name="ir2_joint" type="fixed">
    <axis xyz="1 0 0"/> <!-- 0 1 0 -->
    <origin xyz="0.1225 0.085 -0.1075" rpy="0 0 0.60"/>
    <parent link="base_link"/>
    <child link="sensor/ir2"/>
  </joint>

<link name="sensor/ir2">
      <inertial>
        <mass value="0.001" />
        <origin xyz="0 0 0" rpy="0 0 0" />
        <inertia ixx="0.000000017" ixy="0" ixz="0" iyy="0.000000017" iyz="0" izz="0.000000017" />
      </inertial>
      <visual>
        <origin xyz="0 0 0" rpy="0 0 0" />
        <geometry>
          <mesh filename="package://evarobot_description/meshes/sonar_sensor/max_sonar_ez4.dae"/>
        </geometry>
      </visual>
      <collision>
        <origin xyz="0 0 0" rpy="0 0 0" />
        <geometry>
          <box size="0.01 0.01 0.01" />
        </geometry>
      </collision>
    </link>

<!-- IR2 Plugin -->
 <gazebo reference="sensor/ir2">
      <sensor type="ray" name="ir2">
	  <pose>0 0 0 0 0 0</pose>
	<ray>
          <scan>
            <horizontal>
      	      <samples>320</samples>
      	      <resolution>1</resolution>
      	      <min_angle>-0.001</min_angle>
      	      <max_angle>0.001</max_angle>
            </horizontal>
          </scan>
          <range>
            <min>0.02</min>
            <max>5</max>
            <resolution>0.01</resolution>
          </range>
	</ray>
	<plugin name="ir2_plugin" filename="libim_gazebo_ros_sonar.so">
          <topicName>gazebo/sensor/IR2</topicName>
          <frameName>sensor/ir2</frameName>
	  <frameId>sensor/ir2</frameId>
	  <radiation>infrared</radiation>
	  <fov>0.05</fov>
	  <gaussianNoise>0</gaussianNoise>
	</plugin>
        <always_on>1</always_on>
        <update_rate>4</update_rate>
        <visualize>false</visualize>
      </sensor>
    </gazebo>    
    

</robot>

